Workbook

Sheet Indice
A1: mIA · Índice de seguimiento
A2: Control central de incidencias, tareas, arquitectura, costes y estimaciones. Las tareas iniciales están sembradas desde los documentos aportados; revisa las que figuran «Por validar».
A4: Sección | B4: Qué contiene | C4: N.º de tareas | D4: Pendientes / por validar | E4: Ir a sección
A5: Dashboard | B5: Resumen global de tareas, estados y costes | C5: — | D5: — | E5: Abrir | H5: mia-web: http://localhost:5173/ mia-diagnostics: http://127.0.0.1:5001/api/admin/diagnostics/
A6: Arquitectura | B6: Diagramas, componentes, flujo e incidencias de arquitectura | C6: =COUNTA(Arquitectura!A155:A254) -> 4 | D6: =COUNTIF(Arquitectura!C155:C254,"Pendiente")+COUNTIF(Arquitectura!C155:C254,"Por validar") -> 4 | E6: Abrir
A7: Login y Autenticación | B7: Login, Entra ID, JWT, permisos y sesiones | C7: =COUNTA('Login y Autenticación'!A5:A104) -> 4 | D7: =COUNTIF('Login y Autenticación'!C5:C104,"Pendiente")+COUNTIF('Login y Autenticación'!C5:C104,"Por validar") -> 4 | E7: Abrir
A8: Correo | B8: Integración de correo, Graph y salvaguardas de envío | C8: =COUNTA(Correo!A5:A105) -> 5 | D8: =COUNTIF(Correo!C5:C105,"Pendiente")+COUNTIF(Correo!C5:C105,"Por validar") -> 5 | E8: Abrir
A9: Empleados | B9: Altas, edición, sincronización y datos de empleados | C9: =COUNTA(Empleados!A5:A104) -> 3 | D9: =COUNTIF(Empleados!C5:C104,"Pendiente")+COUNTIF(Empleados!C5:C104,"Por validar") -> 3 | E9: Abrir
A10: Boletines TT | B10: Tareas relacionadas con boletines TT | C10: =COUNTA('Boletines TT'!A5:A104) -> 2 | D10: =COUNTIF('Boletines TT'!C5:C104,"Pendiente")+COUNTIF('Boletines TT'!C5:C104,"Por validar") -> 2 | E10: Abrir
A11: Turnos | B11: Gestión e integración de turnos | C11: =COUNTA(Turnos!A5:A104) -> 2 | D11: =COUNTIF(Turnos!C5:C104,"Pendiente")+COUNTIF(Turnos!C5:C104,"Por validar") -> 2 | E11: Abrir
A12: Fichajes | B12: Fichajes y validaciones asociadas | C12: =COUNTA(Fichajes!A5:A104) -> 4 | D12: =COUNTIF(Fichajes!C5:C104,"Pendiente")+COUNTIF(Fichajes!C5:C104,"Por validar") -> 4 | E12: Abrir
A13: Nominas | B13: Procesos e información de nóminas | C13: =COUNTA(Nominas!A5:A104) -> 4 | D13: =COUNTIF(Nominas!C5:C104,"Pendiente")+COUNTIF(Nominas!C5:C104,"Por validar") -> 4 | E13: Abrir
A14: Vacaciones y Asuntos Propios | B14: Solicitudes, saldos y procesos relacionados | C14: =COUNTA('Vacaciones y Asuntos Propios'!A5:A104) -> 2 | D14: =COUNTIF('Vacaciones y Asuntos Propios'!C5:C104,"Pendiente")+COUNTIF('Vacaciones y Asuntos Propios'!C5:C104,"Por validar") -> 2 | E14: Abrir
A15: Absentismo | B15: Ausencias, reglas y reporting | C15: =COUNTA(Absentismo!A5:A104) -> 2 | D15: =COUNTIF(Absentismo!C5:C104,"Pendiente")+COUNTIF(Absentismo!C5:C104,"Por validar") -> 2 | E15: Abrir
A16: Informes y Reporting | B16: Generación y validación de informes | C16: =COUNTA('Informes y Reporting'!A5:A104) -> 3 | D16: =COUNTIF('Informes y Reporting'!C5:C104,"Pendiente")+COUNTIF('Informes y Reporting'!C5:C104,"Por validar") -> 3 | E16: Abrir
A17: Tratamiento de Adjuntos | B17: Carga, análisis, privacidad y tratamiento de adjuntos | C17: =COUNTA('Tratamiento de Adjuntos'!A5:A104) -> 3 | D17: =COUNTIF('Tratamiento de Adjuntos'!C5:C104,"Pendiente")+COUNTIF('Tratamiento de Adjuntos'!C5:C104,"Por validar") -> 3 | E17: Abrir
A18: Noticias y Newsletter | B18: Noticias, boletines y newsletter | C18: =COUNTA('Noticias y Newsletter'!A5:A104) -> 2 | D18: =COUNTIF('Noticias y Newsletter'!C5:C104,"Pendiente")+COUNTIF('Noticias y Newsletter'!C5:C104,"Por validar") -> 2 | E18: Abrir
A19: Gobernanza | B19: Gobernanza, cambios, decisiones y proceso operativo | C19: =COUNTA(Gobernanza!A5:A104) -> 4 | D19: =COUNTIF(Gobernanza!C5:C104,"Pendiente")+COUNTIF(Gobernanza!C5:C104,"Por validar") -> 4 | E19: Abrir
A20: Auditorias | B20: Auditorías, evidencias y remediaciones | C20: =COUNTA(Auditorias!A5:A104) -> 4 | D20: =COUNTIF(Auditorias!C5:C104,"Pendiente")+COUNTIF(Auditorias!C5:C104,"Por validar") -> 4 | E20: Abrir
A21: Seguridad | B21: Seguridad de aplicación, datos, secretos y controles | C21: =COUNTA(Seguridad!A5:A104) -> 10 | D21: =COUNTIF(Seguridad!C5:C104,"Pendiente")+COUNTIF(Seguridad!C5:C104,"Por validar") -> 10 | E21: Abrir
A22: Preproduccion | B22: Pruebas y criterios de salida a preproducción | C22: =COUNTA(Preproduccion!A5:A104) -> 5 | D22: =COUNTIF(Preproduccion!C5:C104,"Pendiente")+COUNTIF(Preproduccion!C5:C104,"Por validar") -> 5 | E22: Abrir
A23: Produccion | B23: Despliegue, comprobaciones y operación en producción | C23: =COUNTA(Produccion!A5:A104) -> 5 | D23: =COUNTIF(Produccion!C5:C104,"Pendiente")+COUNTIF(Produccion!C5:C104,"Por validar") -> 5 | E23: Abrir
A24: Informe de Costes | B24: Tareas de medición, control y optimización de costes | C24: =COUNTA('Informe de Costes'!A5:A104) -> 5 | D24: =COUNTIF('Informe de Costes'!C5:C104,"Pendiente")+COUNTIF('Informe de Costes'!C5:C104,"Por validar") -> 5 | E24: Abrir
A25: Estimaciones de Horas | B25: Validación de alcance y horas presupuestadas | C25: =COUNTA('Estimaciones de Horas'!A5:A7) -> 3 | D25: =COUNTIF('Estimaciones de Horas'!C5:C7,"Pendiente")+COUNTIF('Estimaciones de Horas'!C5:C7,"Por validar") -> 3 | E25: Abrir
A26: Costes Azure | B26: Escenarios de Azure, LLM, voz y servicios planificados | C26: — | D26: — | E26: Ir a pestaña
A27: Mundo 2D | B27: Interfaz 2D: flujo de conversación, streaming y UX | C27: 6 | D27: 6 | E27: Ir a pestaña
A28: Mundo 3D | B28: Avatar 3D, voz, streaming, rendimiento y permisos | C28: 6 | D28: 6 | E28: Ir a pestaña
A29: Holograma | B29: Experiencia holográfica, dispositivo, privacidad y operación | C29: 6 | D29: 6 | E29: Ir a pestaña
A30: mIA-Desktop | B30: Aplicación de escritorio, autenticación, actualización y seguridad | C30: 6 | D30: 6 | E30: Ir a pestaña
A31: Multiidioma | B31: Idiomas, recursos de traducción, respuestas, documentos y voz | C31: 7 | D31: 7 | E31: Ir a pestaña

Sheet Dashboard
A1: mIA · Dashboard de seguimiento
A2: Resumen automático de las tablas de las pestañas de trabajo. Cambia el estado en cada incidencia y el resumen se recalculará al abrir en Excel.
A4: Indicador | B4: Valor | D4: Estado | E4: Total | F4: % del total
A5: Total de incidencias/tareas | B5: =SUM(B15:B39) -> 107 | D5: Pendiente | E5: =B6 -> 61 | F5: =IFERROR(E5/$B$5,0) -> 0.57009346
A6: Pendiente | B6: =SUM(C15:C39) -> 61 | D6: En curso | E6: =B7 -> 0 | F6: =IFERROR(E6/$B$5,0) -> 0
A7: En curso | B7: =SUM(D15:D39) -> 0 | D7: Bloqueado | E7: =B8 -> 0 | F7: =IFERROR(E7/$B$5,0) -> 0
A8: Bloqueado | B8: =SUM(E15:E39) -> 0 | D8: Por validar | E8: =B9 -> 46 | F8: =IFERROR(E8/$B$5,0) -> 0.42990654
A9: Por validar | B9: =SUM(F15:F39) -> 46 | D9: Resuelto | E9: =B10 -> 0 | F9: =IFERROR(E9/$B$5,0) -> 0
A10: Resuelto | B10: =SUM(G15:G39) -> 0 | D10: Descartado | E10: =B11 -> 0 | F10: =IFERROR(E10/$B$5,0) -> 0
A11: Descartado | B11: =COUNTIF(Arquitectura!C155:C254,"Descartado")+COUNTIF('Login y Autenticación'!C5:C104,"Descartado")+COUNTIF(Correo!C5:C105,"Descartado")+COUNTIF(Empleados!C5:C104,"Descartado")+COUNTIF('Boletines TT'!C5:C104,"Descartado")+COUNTIF(Turnos!C5:C104,"Descartado")+COUNTIF(Fichajes!C5:C104,"Descartado")+COUNTIF(Nominas!C5:C104,"Descartado")+COUNTIF('Vacaciones y Asuntos Propios'!C5:C104,"Descartado")+COUNTIF(Absentismo!C5:C104,"Descartado")+COUNTIF('Informes y Reporting'!C5:C104,"Descartado")+COUNTIF('Tratamiento de Adjuntos'!C5:C104,"Descartado")+COUNTIF('Noticias y Newsletter'!C5:C104,"Descartado")+COUNTIF(Gobernanza!C5:C104,"Descartado")+COUNTIF(Auditorias!C5:C104,"Descartado")+COUNTIF(Seguridad!C5:C104,"Descartado")+COUNTIF(Preproduccion!C5:C104,"Descartado")+COUNTIF(Produccion!C5:C104,"Descartado")+COUNTIF('Informe de Costes'!C5:C104,"Descartado")+COUNTIF('Estimaciones de Horas'!C5:C7,"Descartado")+COUNTIF('Mundo 2D'!C5:C104,"Descartado")+COUNTIF('Mundo 3D'!C5:C104,"Descartado")+COUNTIF(Holograma!C5:C104,"Descartado")+COUNTIF('mIA-Desktop'!C5:C104,"Descartado")+COUNTIF(Multiidioma!C5:C104,"Descartado") -> 0
A12: Nota: el estado inicial de las tareas es una propuesta basada en las presentaciones/documentos, no una confirmación del estado real del repositorio o del trabajo ya realizado.
A14: Sección | B14: Tareas | C14: Pendiente | D14: En curso | E14: Bloqueado | F14: Por validar | G14: Resuelto | H14: % resuelto
A15: Arquitectura | B15: =COUNTA(Arquitectura!A155:A254) -> 4 | C15: =COUNTIF(Arquitectura!C155:C254,"Pendiente") -> 2 | D15: =COUNTIF(Arquitectura!C155:C254,"En curso") -> 0 | E15: =COUNTIF(Arquitectura!C155:C254,"Bloqueado") -> 0 | F15: =COUNTIF(Arquitectura!C155:C254,"Por validar") -> 2 | G15: =COUNTIF(Arquitectura!C155:C254,"Resuelto") -> 0 | H15: =IFERROR(G15/B15,0) -> 0
A16: Login y Autenticación | B16: =COUNTA('Login y Autenticación'!A5:A104) -> 4 | C16: =COUNTIF('Login y Autenticación'!C5:C104,"Pendiente") -> 2 | D16: =COUNTIF('Login y Autenticación'!C5:C104,"En curso") -> 0 | E16: =COUNTIF('Login y Autenticación'!C5:C104,"Bloqueado") -> 0 | F16: =COUNTIF('Login y Autenticación'!C5:C104,"Por validar") -> 2 | G16: =COUNTIF('Login y Autenticación'!C5:C104,"Resuelto") -> 0 | H16: =IFERROR(G16/B16,0) -> 0
A17: Correo | B17: =COUNTA(Correo!A5:A105) -> 5 | C17: =COUNTIF(Correo!C5:C105,"Pendiente") -> 4 | D17: =COUNTIF(Correo!C5:C105,"En curso") -> 0 | E17: =COUNTIF(Correo!C5:C105,"Bloqueado") -> 0 | F17: =COUNTIF(Correo!C5:C105,"Por validar") -> 1 | G17: =COUNTIF(Correo!C5:C105,"Resuelto") -> 0 | H17: =IFERROR(G17/B17,0) -> 0
A18: Empleados | B18: =COUNTA(Empleados!A5:A104) -> 3 | C18: =COUNTIF(Empleados!C5:C104,"Pendiente") -> 1 | D18: =COUNTIF(Empleados!C5:C104,"En curso") -> 0 | E18: =COUNTIF(Empleados!C5:C104,"Bloqueado") -> 0 | F18: =COUNTIF(Empleados!C5:C104,"Por validar") -> 2 | G18: =COUNTIF(Empleados!C5:C104,"Resuelto") -> 0 | H18: =IFERROR(G18/B18,0) -> 0
A19: Boletines TT | B19: =COUNTA('Boletines TT'!A5:A104) -> 2 | C19: =COUNTIF('Boletines TT'!C5:C104,"Pendiente") -> 1 | D19: =COUNTIF('Boletines TT'!C5:C104,"En curso") -> 0 | E19: =COUNTIF('Boletines TT'!C5:C104,"Bloqueado") -> 0 | F19: =COUNTIF('Boletines TT'!C5:C104,"Por validar") -> 1 | G19: =COUNTIF('Boletines TT'!C5:C104,"Resuelto") -> 0 | H19: =IFERROR(G19/B19,0) -> 0
A20: Turnos | B20: =COUNTA(Turnos!A5:A104) -> 2 | C20: =COUNTIF(Turnos!C5:C104,"Pendiente") -> 1 | D20: =COUNTIF(Turnos!C5:C104,"En curso") -> 0 | E20: =COUNTIF(Turnos!C5:C104,"Bloqueado") -> 0 | F20: =COUNTIF(Turnos!C5:C104,"Por validar") -> 1 | G20: =COUNTIF(Turnos!C5:C104,"Resuelto") -> 0 | H20: =IFERROR(G20/B20,0) -> 0
A21: Fichajes | B21: =COUNTA(Fichajes!A5:A104) -> 4 | C21: =COUNTIF(Fichajes!C5:C104,"Pendiente") -> 4 | D21: =COUNTIF(Fichajes!C5:C104,"En curso") -> 0 | E21: =COUNTIF(Fichajes!C5:C104,"Bloqueado") -> 0 | F21: =COUNTIF(Fichajes!C5:C104,"Por validar") -> 0 | G21: =COUNTIF(Fichajes!C5:C104,"Resuelto") -> 0 | H21: =IFERROR(G21/B21,0) -> 0
A22: Nominas | B22: =COUNTA(Nominas!A5:A104) -> 4 | C22: =COUNTIF(Nominas!C5:C104,"Pendiente") -> 1 | D22: =COUNTIF(Nominas!C5:C104,"En curso") -> 0 | E22: =COUNTIF(Nominas!C5:C104,"Bloqueado") -> 0 | F22: =COUNTIF(Nominas!C5:C104,"Por validar") -> 3 | G22: =COUNTIF(Nominas!C5:C104,"Resuelto") -> 0 | H22: =IFERROR(G22/B22,0) -> 0
A23: Vacaciones y Asuntos Propios | B23: =COUNTA('Vacaciones y Asuntos Propios'!A5:A104) -> 2 | C23: =COUNTIF('Vacaciones y Asuntos Propios'!C5:C104,"Pendiente") -> 1 | D23: =COUNTIF('Vacaciones y Asuntos Propios'!C5:C104,"En curso") -> 0 | E23: =COUNTIF('Vacaciones y Asuntos Propios'!C5:C104,"Bloqueado") -> 0 | F23: =COUNTIF('Vacaciones y Asuntos Propios'!C5:C104,"Por validar") -> 1 | G23: =COUNTIF('Vacaciones y Asuntos Propios'!C5:C104,"Resuelto") -> 0 | H23: =IFERROR(G23/B23,0) -> 0
A24: Absentismo | B24: =COUNTA(Absentismo!A5:A104) -> 2 | C24: =COUNTIF(Absentismo!C5:C104,"Pendiente") -> 1 | D24: =COUNTIF(Absentismo!C5:C104,"En curso") -> 0 | E24: =COUNTIF(Absentismo!C5:C104,"Bloqueado") -> 0 | F24: =COUNTIF(Absentismo!C5:C104,"Por validar") -> 1 | G24: =COUNTIF(Absentismo!C5:C104,"Resuelto") -> 0 | H24: =IFERROR(G24/B24,0) -> 0
A25: Informes y Reporting | B25: =COUNTA('Informes y Reporting'!A5:A104) -> 3 | C25: =COUNTIF('Informes y Reporting'!C5:C104,"Pendiente") -> 2 | D25: =COUNTIF('Informes y Reporting'!C5:C104,"En curso") -> 0 | E25: =COUNTIF('Informes y Reporting'!C5:C104,"Bloqueado") -> 0 | F25: =COUNTIF('Informes y Reporting'!C5:C104,"Por validar") -> 1 | G25: =COUNTIF('Informes y Reporting'!C5:C104,"Resuelto") -> 0 | H25: =IFERROR(G25/B25,0) -> 0
A26: Tratamiento de Adjuntos | B26: =COUNTA('Tratamiento de Adjuntos'!A5:A104) -> 3 | C26: =COUNTIF('Tratamiento de Adjuntos'!C5:C104,"Pendiente") -> 1 | D26: =COUNTIF('Tratamiento de Adjuntos'!C5:C104,"En curso") -> 0 | E26: =COUNTIF('Tratamiento de Adjuntos'!C5:C104,"Bloqueado") -> 0 | F26: =COUNTIF('Tratamiento de Adjuntos'!C5:C104,"Por validar") -> 2 | G26: =COUNTIF('Tratamiento de Adjuntos'!C5:C104,"Resuelto") -> 0 | H26: =IFERROR(G26/B26,0) -> 0
A27: Noticias y Newsletter | B27: =COUNTA('Noticias y Newsletter'!A5:A104) -> 2 | C27: =COUNTIF('Noticias y Newsletter'!C5:C104,"Pendiente") -> 1 | D27: =COUNTIF('Noticias y Newsletter'!C5:C104,"En curso") -> 0 | E27: =COUNTIF('Noticias y Newsletter'!C5:C104,"Bloqueado") -> 0 | F27: =COUNTIF('Noticias y Newsletter'!C5:C104,"Por validar") -> 1 | G27: =COUNTIF('Noticias y Newsletter'!C5:C104,"Resuelto") -> 0 | H27: =IFERROR(G27/B27,0) -> 0
A28: Gobernanza | B28: =COUNTA(Gobernanza!A5:A104) -> 4 | C28: =COUNTIF(Gobernanza!C5:C104,"Pendiente") -> 4 | D28: =COUNTIF(Gobernanza!C5:C104,"En curso") -> 0 | E28: =COUNTIF(Gobernanza!C5:C104,"Bloqueado") -> 0 | F28: =COUNTIF(Gobernanza!C5:C104,"Por validar") -> 0 | G28: =COUNTIF(Gobernanza!C5:C104,"Resuelto") -> 0 | H28: =IFERROR(G28/B28,0) -> 0
A29: Auditorias | B29: =COUNTA(Auditorias!A5:A104) -> 4 | C29: =COUNTIF(Auditorias!C5:C104,"Pendiente") -> 4 | D29: =COUNTIF(Auditorias!C5:C104,"En curso") -> 0 | E29: =COUNTIF(Auditorias!C5:C104,"Bloqueado") -> 0 | F29: =COUNTIF(Auditorias!C5:C104,"Por validar") -> 0 | G29: =COUNTIF(Auditorias!C5:C104,"Resuelto") -> 0 | H29: =IFERROR(G29/B29,0) -> 0
A30: Seguridad | B30: =COUNTA(Seguridad!A5:A104) -> 10 | C30: =COUNTIF(Seguridad!C5:C104,"Pendiente") -> 10 | D30: =COUNTIF(Seguridad!C5:C104,"En curso") -> 0 | E30: =COUNTIF(Seguridad!C5:C104,"Bloqueado") -> 0 | F30: =COUNTIF(Seguridad!C5:C104,"Por validar") -> 0 | G30: =COUNTIF(Seguridad!C5:C104,"Resuelto") -> 0 | H30: =IFERROR(G30/B30,0) -> 0
A31: Preproduccion | B31: =COUNTA(Preproduccion!A5:A104) -> 5 | C31: =COUNTIF(Preproduccion!C5:C104,"Pendiente") -> 5 | D31: =COUNTIF(Preproduccion!C5:C104,"En curso") -> 0 | E31: =COUNTIF(Preproduccion!C5:C104,"Bloqueado") -> 0 | F31: =COUNTIF(Preproduccion!C5:C104,"Por validar") -> 0 | G31: =COUNTIF(Preproduccion!C5:C104,"Resuelto") -> 0 | H31: =IFERROR(G31/B31,0) -> 0
A32: Produccion | B32: =COUNTA(Produccion!A5:A104) -> 5 | C32: =COUNTIF(Produccion!C5:C104,"Pendiente") -> 5 | D32: =COUNTIF(Produccion!C5:C104,"En curso") -> 0 | E32: =COUNTIF(Produccion!C5:C104,"Bloqueado") -> 0 | F32: =COUNTIF(Produccion!C5:C104,"Por validar") -> 0 | G32: =COUNTIF(Produccion!C5:C104,"Resuelto") -> 0 | H32: =IFERROR(G32/B32,0) -> 0
A33: Informe de Costes | B33: =COUNTA('Informe de Costes'!A5:A104) -> 5 | C33: =COUNTIF('Informe de Costes'!C5:C104,"Pendiente") -> 5 | D33: =COUNTIF('Informe de Costes'!C5:C104,"En curso") -> 0 | E33: =COUNTIF('Informe de Costes'!C5:C104,"Bloqueado") -> 0 | F33: =COUNTIF('Informe de Costes'!C5:C104,"Por validar") -> 0 | G33: =COUNTIF('Informe de Costes'!C5:C104,"Resuelto") -> 0 | H33: =IFERROR(G33/B33,0) -> 0
A34: Estimaciones de Horas | B34: =COUNTA('Estimaciones de Horas'!A5:A7) -> 3 | C34: =COUNTIF('Estimaciones de Horas'!C5:C7,"Pendiente") -> 1 | D34: =COUNTIF('Estimaciones de Horas'!C5:C7,"En curso") -> 0 | E34: =COUNTIF('Estimaciones de Horas'!C5:C7,"Bloqueado") -> 0 | F34: =COUNTIF('Estimaciones de Horas'!C5:C7,"Por validar") -> 2 | G34: =COUNTIF('Estimaciones de Horas'!C5:C7,"Resuelto") -> 0 | H34: =IFERROR(G34/B34,0) -> 0
A35: Mundo 2D | B35: =COUNTA('Mundo 2D'!A5:A104) -> 6 | C35: =COUNTIF('Mundo 2D'!C5:C104,"Pendiente") -> 1 | D35: =COUNTIF('Mundo 2D'!C5:C104,"En curso") -> 0 | E35: =COUNTIF('Mundo 2D'!C5:C104,"Bloqueado") -> 0 | F35: =COUNTIF('Mundo 2D'!C5:C104,"Por validar") -> 5 | G35: =COUNTIF('Mundo 2D'!C5:C104,"Resuelto") -> 0 | H35: =IFERROR(G35/B35,0) -> 0
A36: Mundo 3D | B36: =COUNTA('Mundo 3D'!A5:A104) -> 6 | C36: =COUNTIF('Mundo 3D'!C5:C104,"Pendiente") -> 1 | D36: =COUNTIF('Mundo 3D'!C5:C104,"En curso") -> 0 | E36: =COUNTIF('Mundo 3D'!C5:C104,"Bloqueado") -> 0 | F36: =COUNTIF('Mundo 3D'!C5:C104,"Por validar") -> 5 | G36: =COUNTIF('Mundo 3D'!C5:C104,"Resuelto") -> 0 | H36: =IFERROR(G36/B36,0) -> 0
A37: Holograma | B37: =COUNTA(Holograma!A5:A104) -> 6 | C37: =COUNTIF(Holograma!C5:C104,"Pendiente") -> 1 | D37: =COUNTIF(Holograma!C5:C104,"En curso") -> 0 | E37: =COUNTIF(Holograma!C5:C104,"Bloqueado") -> 0 | F37: =COUNTIF(Holograma!C5:C104,"Por validar") -> 5 | G37: =COUNTIF(Holograma!C5:C104,"Resuelto") -> 0 | H37: =IFERROR(G37/B37,0) -> 0
A38: mIA-Desktop | B38: =COUNTA('mIA-Desktop'!A5:A104) -> 6 | C38: =COUNTIF('mIA-Desktop'!C5:C104,"Pendiente") -> 1 | D38: =COUNTIF('mIA-Desktop'!C5:C104,"En curso") -> 0 | E38: =COUNTIF('mIA-Desktop'!C5:C104,"Bloqueado") -> 0 | F38: =COUNTIF('mIA-Desktop'!C5:C104,"Por validar") -> 5 | G38: =COUNTIF('mIA-Desktop'!C5:C104,"Resuelto") -> 0 | H38: =IFERROR(G38/B38,0) -> 0
A39: Multiidioma | B39: =COUNTA(Multiidioma!A5:A104) -> 7 | C39: =COUNTIF(Multiidioma!C5:C104,"Pendiente") -> 1 | D39: =COUNTIF(Multiidioma!C5:C104,"En curso") -> 0 | E39: =COUNTIF(Multiidioma!C5:C104,"Bloqueado") -> 0 | F39: =COUNTIF(Multiidioma!C5:C104,"Por validar") -> 6 | G39: =COUNTIF(Multiidioma!C5:C104,"Resuelto") -> 0 | H39: =IFERROR(G39/B39,0) -> 0
A45: Costes estimados de referencia
A46: Concepto | B46: Importe | C46: Unidad / nota
A47: Presupuesto Parte A | B47: 50400 | C47: € sin IVA · 1.120 h × 45 €/h
...

Sheet Arquitectura
A1: mIA · Arquitectura y esquemas | J1: ↩ Índice
A2: Esquema funcional reconstruido y láminas originales de la presentación de arquitectura/seguridad aportada. Los esquemas visuales se incluyen como referencia; la lista de tareas sigue siendo editable.
A4: FLUJO PRINCIPAL DE UNA PETICIÓN
A5: 1 · Usuario / Frontend | C5: Interfaces 2D, 3D y holograma; MSAL.js; token Bearer
A6: ↓
A7: 2 · Identidad | C7: Entra ID · validación JWT (firma RS256/JWKS, aud, iss, exp) · roles/permisos
A8: ↓
A9: 3 · API / Backend | C9: FastAPI · validación Pydantic · request_id · control de sesión por (session_id, user_id)
A10: ↓
A11: 4 · Orquestador | C11: Enrutado determinista por dominio · herramientas autorizadas
A12: ↓
A13: 5 · Privacy Gateway | C13: Presidio/tokenización de PII antes de llamada al LLM (depende de configuración enabled=true)
A14: ↓
A15: 6 · Proveedor LLM | C15: OpenAI / Azure OpenAI · máximo 8 rondas de herramientas · presupuesto de 120 s/turno
A16: ↓
A17: 7 · Respuesta | C17: Restauración de tokens · salvaguardas de voz · ElevenLabs para síntesis
A19: COMPONENTES Y ESTADO SEGÚN LA PRESENTACIÓN
A20: Componente | B20: Estado documentado | C20: Notas
A21: Frontend 2D/3D/holograma | B21: Implementado | C21: Comparten sesión y API; revisar CSP/HSTS.
A22: API FastAPI | B22: Parcial | C22: Validación y errores; falta rate limiting.
A23: Auth Entra ID/MSAL/JWT | B23: Implementado | C23: Pendiente decisión de configuración definitiva con IT.
A24: Privacy Gateway / Presidio | B24: Implementado con condición | C24: Protege salida al LLM cuando enabled=true; verificar configuración real de producción.
A25: OpenAI / Azure OpenAI | B25: Implementado | C25: Proveedor común; controlar consumo por usuario.
A26: PostgreSQL + pgvector | B26: Implementado | C26: Base relacional e índice vectorial; Azure AI Search no desplegado.
A27: SharePoint / Graph | B27: Implementado | C27: Job de sincronización: comando de despliegue incorrecto según auditoría.
A28: ElevenLabs | B28: Parcial | C28: Filtro de importes; falta filtrado general de PII antes de voz.
A29: Azure Machine Learning / predictivo | B29: No implementado | C29: La presentación indica que no existe código ni infraestructura de ML.
A30: Conectia / A3 | B30: Planificado | C30: Parte B del presupuesto; integración de fichajes y datos RR. HH.
A32: LÁMINAS ORIGINALES DE ARQUITECTURA / DESPLIEGUE
A33: Presentación de arquitectura · diapositiva 4
A72: Presentación de arquitectura · diapositiva 5
A111: Presentación de arquitectura · diapositiva 20
A150: Presentación de arquitectura · diapositiva 21
A153: INCIDENCIAS Y TAREAS DE ARQUITECTURA
A154: Incidencia / ID | B154: Descripción | C154: Estado | D154: Prioridad | E154: Responsable | F154: Estimación (h) | G154: Observaciones / fuente | H154: Fecha objetivo
A155: ARQ-001 | B155: Documentar el diagrama C4 (contexto, contenedores y componentes) | C155: Por validar | D155: Alta | E155: Desarrollo | F155: 12 | G155: Auditoría/arquitectura: diagramas generales presentes; completar C4 operativo.
A156: ARQ-002 | B156: Confirmar y documentar límites entre frontend, API, orquestador, dominios, LLM y Privacy Gateway | C156: Por validar | D156: Media | E156: Desarrollo | F156: 6 | G156: Basado en el esquema de arquitectura de la presentación.
A157: ARQ-003 | B157: Documentar RAG/pgvector, indexación, permisos y ciclo de actualización | C157: Pendiente | D157: Alta | E157: Desarrollo | F157: 8 | G157: Azure AI Search está planificado, no desplegado; hoy se usa pgvector.
A158: ARQ-004 | B158: Definir hoja de ruta para dominios Finanzas, Administración, Legal y Compliance | C158: Pendiente | D158: Media | E158: Producto/Desarrollo | F158: 12 | G158: La presentación indica que estos dominios están previstos, no implementados.

Sheet Login y Autenticación
A1: Login y Autenticación | J1: ↩ Índice
A2: Registro de incidencias, tareas y validaciones. Actualiza el Estado desde el desplegable; las tareas iniciales provienen de los documentos aportados y algunas requieren confirmar alcance.
A4: Incidencia / ID | B4: Descripción | C4: Estado | D4: Prioridad | E4: Responsable | F4: Estimación (h) | G4: Observaciones / fuente | H4: Fecha objetivo
A5: AUTH-001 | B5: Decidir con IT el modo de login definitivo: Easy Auth o modo Entra implementado | C5: Pendiente | D5: Alta | E5: IT + Desarrollo | F5: 3 | G5: Decisión pendiente en checklist previo a producción.
A6: AUTH-002 | B6: Verificar configuración real de audiencia, issuer, JWKS y grupos/roles en el tenant | C6: Por validar | D6: Alta | E6: IT | F6: 4 | G6: La validación JWT y permisos granulares constan como implementados; confirmar tenant.
A7: AUTH-003 | B7: Confirmar el alcance exacto de permisos de SharePoint concedidos en Entra ID | C7: Pendiente | D7: Alta | E7: IT | F7: 3 | G7: La auditoría recomienda acotar a Sites.Selected si es viable.
A8: AUTH-004 | B8: Verificar pantalla de acceso restringido y matriz de permisos por rol | C8: Por validar | D8: Media | E8: Desarrollo + IT | F8: 4 | G8: MSAL.js y control por roles constan implementados.

Sheet Correo
A1: Correo | J1: ↩ Índice
A2: Registro de incidencias, tareas y validaciones. Actualiza el Estado desde el desplegable; las tareas iniciales provienen de los documentos aportados y algunas requieren confirmar alcance.
A4: Incidencia / ID | B4: Descripción | C4: Estado | D4: Prioridad | E4: Responsable | F4: Estimación (h) | G4: Observaciones / fuente | H4: Fecha objetivo
A5: MAIL-001 | B5: Confirmar Application Access Policy de Exchange Online | C5: Pendiente | D5: Alta | E5: IT | F5: 3 | G5: Pendiente explícito para IT antes de producción.
A6: MAIL-002 | B6: Revisar permisos y alcance de lectura de correo mediante Microsoft Graph | C6: Pendiente | D6: Alta | E6: IT + Desarrollo | F6: 4 | G6: La presentación marca el alcance del correo como punto a confirmar.
A7: MAIL-003 | B7: Validar salvaguardas de envío: borrador, pausa humana, buzón de origen y destinatarios | C7: Por validar | D7: Alta | E7: Desarrollo | F7: 5 | G7: La auditoría describe cinco condiciones antes del envío real.
A8: MAIL-004 | B8: Asegurar que el envío real permanece desactivado hasta autorización formal | C8: Pendiente | D8: Alta | E8: IT + Desarrollo | F8: 1 | G8: MIA_MAIL__SEND_ENABLED desactivado por defecto.
A9: MAIL-005 | B9: Cuando recibe un nuevo mail, y avisa con el globo o el alert, mIA debe decirlo por voz y preguntar si quiere que se lo resuma, en caso afirmativo debe resumir el ultimo mail recibido y mostrar en pantalla el registro como cuando se pregunta por el listado, con las opciones de ver y responder. | C9: Pendiente | D9: Muy Alta | E9: Desarrollo

Sheet Empleados
A1: Empleados | J1: ↩ Índice
A2: Registro de incidencias, tareas y validaciones. Actualiza el Estado desde el desplegable; las tareas iniciales provienen de los documentos aportados y algunas requieren confirmar alcance.
A4: Incidencia / ID | B4: Descripción | C4: Estado | D4: Prioridad | E4: Responsable | F4: Estimación (h) | G4: Observaciones / fuente | H4: Fecha objetivo
A5: EMP-001 | B5: Validar sincronización de empleados SharePoint/Graph a PostgreSQL | C5: Por validar | D5: Alta | E5: Desarrollo | F5: 5 | G5: El job de sincronización tiene un comando incorrecto actualmente.
A6: EMP-002 | B6: Validar altas, edición y campos de sexo/nacionalidad en formularios y automatización | C6: Pendiente | D6: Media | E6: Desarrollo | F6: 6 | G6: Sincronizar y actulizar los esquemas con los dos nuevos campos. Datos importantes para la estadistica
A7: EMP-003 | B7: Comprobar exclusión de cuentas de prueba de la sincronización real | C7: Por validar | D7: Media | E7: Desarrollo | F7: 2 | G7: La auditoría indica que existe y está cubierta por tests.

Sheet Boletines TT
A1: Boletines TT | J1: ↩ Índice
A2: Registro de incidencias, tareas y validaciones. Actualiza el Estado desde el desplegable; las tareas iniciales provienen de los documentos aportados y algunas requieren confirmar alcance.
A4: Incidencia / ID | B4: Descripción | C4: Estado | D4: Prioridad | E4: Responsable | F4: Estimación (h) | G4: Observaciones / fuente | H4: Fecha objetivo
A5: BTT-001 | B5: Confirmar alcance funcional y fuente de datos de Boletines TT | C5: Por validar | D5: Media | E5: Producto/Desarrollo | F5: 3 | G5: No se especifica detalle funcional en los documentos aportados.
A6: BTT-002 | B6: Probar generación, consulta y permisos de boletines TT | C6: Pendiente | D6: Media | E6: QA/Desarrollo | F6: 5 | G6: Pendiente de validación funcional.

Sheet Turnos
A1: Turnos | J1: ↩ Índice
A2: Registro de incidencias, tareas y validaciones. Actualiza el Estado desde el desplegable; las tareas iniciales provienen de los documentos aportados y algunas requieren confirmar alcance.
A4: Incidencia / ID | B4: Descripción | C4: Estado | D4: Prioridad | E4: Responsable | F4: Estimación (h) | G4: Observaciones / fuente | H4: Fecha objetivo
A5: TURN-001 | B5: Validar sincronización y consulta de turnos desde SharePoint | C5: Por validar | D5: Alta | E5: Desarrollo | F5: 4 | G5: Turnos aparecen entre los datos corporativos integrados.
A6: TURN-002 | B6: Contrastar resultados con los datos de origen y permisos por rol | C6: Pendiente | D6: Media | E6: QA/Desarrollo | F6: 4 | G6: Pendiente de validación funcional.

Sheet Fichajes
A1: Fichajes | J1: ↩ Índice
A2: Registro de incidencias, tareas y validaciones. Actualiza el Estado desde el desplegable; las tareas iniciales provienen de los documentos aportados y algunas requieren confirmar alcance.
A4: Incidencia / ID | B4: Descripción | C4: Estado | D4: Prioridad | E4: Responsable | F4: Estimación (h) | G4: Observaciones / fuente | H4: Fecha objetivo
A5: FIC-001 | B5: Implementar y validar integración con Conectia/A3 para fichajes | C5: Pendiente | D5: Alta | E5: Desarrollo + IT | F5: 60 | G5: Parte B del presupuesto: 60 h, 2.700 €. No figura implementada hoy.
A6: FIC-002 | B6: Mapear campos, tratar errores y validar resultados de fichajes | C6: Pendiente | D6: Alta | E6: Desarrollo | F6: 12 | G6: Incluido en la estimación de integración Conectia; horas desglosadas por validar.
A7: FIC-003 | B7: Revisar informe generado, hacerlo más simple pero con la misma info, por cada empleado una unica pestaña no varias | C7: Pendiente | D7: Alta | E7: Desarrollo
A8: FIC-004 | B8: Si le pido el detalle en la comparacion con turnos de un unico o varios empleados debe resolverlo para esas personas, y no incluir todas o dar error tal como pasa | C8: Pendiente | D8: Alta | E8: Desarrollo | G8: Para la pregunta: compara los fichajes de las fechas en la hoja excel con los turnos asignados para esos empleados, quiero que generes el informe solo para el empleado Alba Fernandez Avila. Responde: No se han generado: Excel. No se confirma una entrega que no existe. No hay datos verificables y completos para exportar desde esta ejecución. 12:29 13.893 ms Análisis Indicadores y comparativas Resultado Persona Alba Fernandez Avila Departamento Pisos Correctos 0 Desviados 0 0 Desviados de turno 0

Sheet Nominas
A1: Nominas | J1: ↩ Índice
A2: Registro de incidencias, tareas y validaciones. Actualiza el Estado desde el desplegable; las tareas iniciales provienen de los documentos aportados y algunas requieren confirmar alcance.
A4: Incidencia / ID | B4: Descripción | C4: Estado | D4: Prioridad | E4: Responsable | F4: Estimación (h) | G4: Observaciones / fuente | H4: Fecha objetivo
A5: NOM-001 | B5: Verificar minimización de datos antes de generar embeddings de nóminas | C5: Por validar | D5: Alta | E5: Desarrollo/Seguridad | F5: 3 | G5: La auditoría describe proyección sin cifras ni datos personales.
A6: NOM-002 | B6: Validar lectura puntual, permisos específicos y auditoría de nóminas | C6: Por validar | D6: Alta | E6: Desarrollo/QA | F6: 4 | G6: Control sensible descrito como implementado; validar casos reales.
A7: NOM-003 | B7: Confirmar que los importes de nómina no se reproducen por voz en todos los flujos | C7: Por validar | D7: Alta | E7: Desarrollo/QA | F7: 4 | G7: La auditoría señala filtro de importes, pero el endpoint de voz no revalida texto.
A8: NOM-004 | B8: Confirmar decisión sobre indexación de contenido sensible | C8: Pendiente | D8: Alta | E8: IT + Legal + Producto | F8: 2 | G8: MIA_DATA__INDEX_SENSITIVE_CONTENT cambia el alcance de retención; false por defecto.

Sheet Vacaciones y Asuntos Propios
A1: Vacaciones y Asuntos Propios | J1: ↩ Índice
A2: Registro de incidencias, tareas y validaciones. Actualiza el Estado desde el desplegable; las tareas iniciales provienen de los documentos aportados y algunas requieren confirmar alcance.
A4: Incidencia / ID | B4: Descripción | C4: Estado | D4: Prioridad | E4: Responsable | F4: Estimación (h) | G4: Observaciones / fuente | H4: Fecha objetivo
A5: VAC-001 | B5: Validar consulta de vacaciones y asuntos propios contra el dato corporativo | C5: Por validar | D5: Media | E5: QA/Desarrollo | F5: 4 | G5: Incluido en la integración de datos corporativos.
A6: VAC-002 | B6: Probar permisos, saldos, fechas y casos límite | C6: Pendiente | D6: Media | E6: QA/Desarrollo | F6: 5 | G6: Pendiente de validación funcional.

Sheet Absentismo
A1: Absentismo | J1: ↩ Índice
A2: Registro de incidencias, tareas y validaciones. Actualiza el Estado desde el desplegable; las tareas iniciales provienen de los documentos aportados y algunas requieren confirmar alcance.
A4: Incidencia / ID | B4: Descripción | C4: Estado | D4: Prioridad | E4: Responsable | F4: Estimación (h) | G4: Observaciones / fuente | H4: Fecha objetivo
A5: ABS-001 | B5: Confirmar fuentes y reglas de absentismo disponibles en el sistema actual | C5: Por validar | D5: Media | E5: Producto/Desarrollo | F5: 3 | G5: Los documentos aportados no detallan este módulo.
A6: ABS-002 | B6: Definir pruebas funcionales, permisos y trazabilidad de consultas | C6: Pendiente | D6: Media | E6: QA/Desarrollo | F6: 4 | G6: Pendiente de definición/validación.

Sheet Informes y Reporting
A1: Informes y Reporting | J1: ↩ Índice
A2: Registro de incidencias, tareas y validaciones. Actualiza el Estado desde el desplegable; las tareas iniciales provienen de los documentos aportados y algunas requieren confirmar alcance.
A4: Incidencia / ID | B4: Descripción | C4: Estado | D4: Prioridad | E4: Responsable | F4: Estimación (h) | G4: Observaciones / fuente | H4: Fecha objetivo
A5: REP-001 | B5: Conectar informes PDF/Excel con Azure Blob Storage en lugar de /tmp | C5: Pendiente | D5: Alta | E5: Desarrollo | F5: 5 | G5: La auditoría indica que Storage existe, pero los informes se escriben en /tmp.
A6: REP-002 | B6: Validar generación y descarga de PDF, Excel y PPTX frente al sistema anterior | C6: Pendiente | D6: Alta | E6: QA/Desarrollo | F6: 10 | G6: Presupuesto: migración funcional y paridad incluye informes PDF/Excel/PPTX.
A7: REP-003 | B7: Verificar worker de informes masivos y decidir si se activa | C7: Por validar | D7: Media | E7: Desarrollo | F7: 3 | G7: El worker aparece desactivado por defecto.

Sheet Tratamiento de Adjuntos
A1: Tratamiento de Adjuntos | J1: ↩ Índice
A2: Registro de incidencias, tareas y validaciones. Actualiza el Estado desde el desplegable; las tareas iniciales provienen de los documentos aportados y algunas requieren confirmar alcance.
A4: Incidencia / ID | B4: Descripción | C4: Estado | D4: Prioridad | E4: Responsable | F4: Estimación (h) | G4: Observaciones / fuente | H4: Fecha objetivo
A5: ATT-001 | B5: Automatizar/validar instalación del modelo spaCy es_core_news_lg en build/despliegue | C5: Pendiente | D5: Alta | E5: Desarrollo | F5: 4 | G5: Hallazgo de fiabilidad: modelo de ~500 MB no se instala automáticamente.
A6: ATT-002 | B6: Validar allowlist, magic-bytes, denylist y protección path-traversal | C6: Por validar | D6: Alta | E6: QA/Seguridad | F6: 4 | G6: Controles descritos como implementados.
A7: ATT-003 | B7: Confirmar persistencia, retención y limpieza de adjuntos del Privacy Gateway | C7: Por validar | D7: Media | E7: Desarrollo/IT | F7: 3 | G7: Hay limpieza horaria; revisar almacenamiento y política.

Sheet Noticias y Newsletter
A1: Noticias y Newsletter | J1: ↩ Índice
A2: Registro de incidencias, tareas y validaciones. Actualiza el Estado desde el desplegable; las tareas iniciales provienen de los documentos aportados y algunas requieren confirmar alcance.
A4: Incidencia / ID | B4: Descripción | C4: Estado | D4: Prioridad | E4: Responsable | F4: Estimación (h) | G4: Observaciones / fuente | H4: Fecha objetivo
A5: NEWS-001 | B5: Definir fuente, frecuencia y filtros de noticias/newsletter | C5: Por validar | D5: Media | E5: Producto | F5: 3 | G5: No se especifica en los documentos aportados.
A6: NEWS-002 | B6: Validar plantilla, destinatarios, consentimiento y trazabilidad del newsletter | C6: Pendiente | D6: Media | E6: Producto/Desarrollo | F6: 5 | G6: Pendiente de definición funcional.

Sheet Gobernanza
A1: Gobernanza | J1: ↩ Índice
A2: Registro de incidencias, tareas y validaciones. Actualiza el Estado desde el desplegable; las tareas iniciales provienen de los documentos aportados y algunas requieren confirmar alcance.
A4: Incidencia / ID | B4: Descripción | C4: Estado | D4: Prioridad | E4: Responsable | F4: Estimación (h) | G4: Observaciones / fuente | H4: Fecha objetivo
A5: GOV-001 | B5: Confirmar base legal, derechos de interesados y responsabilidades RGPD/LOPDGDD con Legal | C5: Pendiente | D5: Alta | E5: IT + Legal | F5: 6 | G5: La auditoría deja estas decisiones fuera del código.
A6: GOV-002 | B6: Valorar DPIA para RR. HH. y, si se desarrolla, para el módulo predictivo | C6: Pendiente | D6: Alta | E6: Legal/DPD | F6: 6 | G6: Recomendación expresa de la presentación.
A7: GOV-003 | B7: Confirmar DPA y condiciones de procesamiento con OpenAI/Azure OpenAI y ElevenLabs | C7: Pendiente | D7: Alta | E7: IT + Legal | F7: 4 | G7: Pendiente explícito antes de procesar datos reales de empleados.
A8: GOV-004 | B8: Definir dominios funcionales y responsables de aprobación de cambios | C8: Pendiente | D8: Media | E8: Producto/IT | F8: 4 | G8: Gobernanza operativa pendiente de concretar.

Sheet Auditorias
A1: Auditorias | J1: ↩ Índice
A2: Registro de incidencias, tareas y validaciones. Actualiza el Estado desde el desplegable; las tareas iniciales provienen de los documentos aportados y algunas requieren confirmar alcance.
A4: Incidencia / ID | B4: Descripción | C4: Estado | D4: Prioridad | E4: Responsable | F4: Estimación (h) | G4: Observaciones / fuente | H4: Fecha objetivo
A5: AUD-001 | B5: Definir integración con SIEM corporativo o documentar decisión de no integración | C5: Pendiente | D5: Media | E5: IT/Seguridad | F5: 4 | G5: La auditoría indica que no hay integración SIEM definida.
A6: AUD-002 | B6: Definir alertas automáticas sobre logs y Application Insights | C6: Pendiente | D6: Alta | E6: IT/Desarrollo | F6: 5 | G6: No hay metricAlerts/actionGroups definidos en Bicep.
A7: AUD-003 | B7: Documentar proceso formal de respuesta a incidentes | C7: Pendiente | D7: Alta | E7: IT/Seguridad | F7: 6 | G7: La presentación indica que no existe proceso formal documentado.
A8: AUD-004 | B8: Revisar matriz de controles y evidencias para aceptación previa a producción | C8: Pendiente | D8: Alta | E8: IT + Desarrollo | F8: 6 | G8: La auditoría indica 61% de controles implementados/verificados.

Sheet Seguridad
A1: Seguridad | J1: ↩ Índice
A2: Registro de incidencias, tareas y validaciones. Actualiza el Estado desde el desplegable; las tareas iniciales provienen de los documentos aportados y algunas requieren confirmar alcance.
A4: Incidencia / ID | B4: Descripción | C4: Estado | D4: Prioridad | E4: Responsable | F4: Estimación (h) | G4: Observaciones / fuente | H4: Fecha objetivo
A5: SEC-001 | B5: Añadir rate limiting a /api/chat/stream y /api/voice/stream | C5: Pendiente | D5: Crítica | E5: Desarrollo | F5: 6 | G5: Hallazgo de prioridad alta: riesgo de abuso de coste y denegación de servicio.
A6: SEC-002 | B6: Añadir cuotas/límites de coste por usuario o sesión | C6: Pendiente | D6: Alta | E6: Desarrollo | F6: 6 | G6: No hay límites agregados de coste por usuario.
A7: SEC-003 | B7: Añadir cabeceras Content-Security-Policy y Strict-Transport-Security | C7: Pendiente | D7: Alta | E7: Desarrollo | F7: 4 | G7: Ausentes según auditoría, especialmente relevante para el frontend 2D legacy.
A8: SEC-004 | B8: Activar Dependabot y escaneo de vulnerabilidades en CI (backend, npm e imagen) | C8: Pendiente | D8: Alta | E8: Desarrollo | F8: 6 | G8: No hay SCA ni escaneo de imagen configurados.
A9: SEC-005 | B9: Crear lockfile reproducible para dependencias Python | C9: Pendiente | D9: Alta | E9: Desarrollo | F9: 3 | G9: Backend usa rangos de versiones sin lockfile.
A10: SEC-006 | B10: Filtrar PII general antes de enviar texto a ElevenLabs y revalidar endpoint de voz | C10: Pendiente | D10: Alta | E10: Desarrollo | F10: 6 | G10: La voz elimina importes, pero no filtra PII general.
A11: SEC-007 | B11: Revisar el enrutado de preguntas ambiguas y aplicar herramientas de menor privilegio | C11: Pendiente | D11: Media | E11: Desarrollo | F11: 5 | G11: El orquestador entrega el catálogo completo de herramientas permitidas si no detecta dominio.
A12: SEC-008 | B12: Confirmar Privacy Gateway enabled=true y fail-closed en configuración real de producción | C12: Pendiente | D12: Crítica | E12: IT + Desarrollo | F12: 3 | G12: La garantía depende de la configuración de entorno en Azure.
A13: SEC-009 | B13: Evaluar VNet/private endpoint para PostgreSQL | C13: Pendiente | D13: Media | E13: IT/Azure | F13: 8 | G13: Planificado; hoy firewall usa AllowAzureServices.
A14: SEC-010 | B14: Definir RTO/RPO, pruebas de restauración y procedimiento de rotación de secretos | C14: Pendiente | D14: Media | E14: IT/Seguridad | F14: 6 | G14: Backups configurados, pero RTO/RPO y respuesta formal no están definidos.

Sheet Preproduccion
A1: Preproduccion | J1: ↩ Índice
A2: Registro de incidencias, tareas y validaciones. Actualiza el Estado desde el desplegable; las tareas iniciales provienen de los documentos aportados y algunas requieren confirmar alcance.
A4: Incidencia / ID | B4: Descripción | C4: Estado | D4: Prioridad | E4: Responsable | F4: Estimación (h) | G4: Observaciones / fuente | H4: Fecha objetivo
A5: PRE-001 | B5: Corregir el comando del job de sincronización en Bicep: mia.sync → mia.ingestion.sync | C5: Pendiente | D5: Crítica | E5: Desarrollo | F5: 1 | G5: Defecto confirmado: el job falla en cada ejecución.
A6: PRE-002 | B6: Ejecutar pruebas de salud /health/live y /health/ready tras despliegue | C6: Pendiente | D6: Alta | E6: Desarrollo/QA | F6: 2 | G6: 200 en ready debe confirmar conexión real a PostgreSQL.
A7: PRE-003 | B7: Completar pruebas de aceptación funcional, carga y concurrencia | C7: Pendiente | D7: Alta | E7: QA/Producto | F7: 16 | G7: Parte del plan de pruebas y validación del presupuesto.
A8: PRE-004 | B8: Verificar instalación del modelo Presidio/spaCy en contenedor limpio | C8: Pendiente | D8: Alta | E8: Desarrollo | F8: 4 | G8: Paso manual que debe automatizarse.
A9: PRE-005 | B9: Validar migraciones Alembic y plan de rollback de base de datos | C9: Pendiente | D9: Alta | E9: Desarrollo/IT | F9: 4 | G9: Rollback de código no revierte migraciones.

Sheet Produccion
A1: Produccion | J1: ↩ Índice
A2: Registro de incidencias, tareas y validaciones. Actualiza el Estado desde el desplegable; las tareas iniciales provienen de los documentos aportados y algunas requieren confirmar alcance.
A4: Incidencia / ID | B4: Descripción | C4: Estado | D4: Prioridad | E4: Responsable | F4: Estimación (h) | G4: Observaciones / fuente | H4: Fecha objetivo
A5: PRO-001 | B5: Acordar y ejecutar checklist de salida a producción con IT | C5: Pendiente | D5: Crítica | E5: IT + Desarrollo | F5: 8 | G5: La presentación indica que producción es el último paso y aún no está contratada.
A6: PRO-002 | B6: Configurar CI/CD completo o documentar el despliegue manual aceptado | C6: Pendiente | D6: Alta | E6: Desarrollo/IT | F6: 8 | G6: La auditoría indica que el despliegue a Azure es manual.
A7: PRO-003 | B7: Confirmar SKU de PostgreSQL y capacidad esperada | C7: Pendiente | D7: Media | E7: IT | F7: 2 | G7: Decisión pendiente de IT.
A8: PRO-004 | B8: Validar DNS, certificados, seguridad, monitorización y distribución Desktop | C8: Pendiente | D8: Alta | E8: IT + Desarrollo | F8: 10 | G8: Parte B incluye despliegue productivo y distribución.
A9: PRO-005 | B9: Confirmar acceso administrativo del cliente a Azure, repositorio y secretos | C9: Pendiente | D9: Alta | E9: IT + Desarrollo | F9: 3 | G9: Condición de traspaso limpio.

Sheet Informe de Costes
A1: Informe de Costes | J1: ↩ Índice
A2: Registro de incidencias, tareas y validaciones. Actualiza el Estado desde el desplegable; las tareas iniciales provienen de los documentos aportados y algunas requieren confirmar alcance.
A4: Incidencia / ID | B4: Descripción | C4: Estado | D4: Prioridad | E4: Responsable | F4: Estimación (h) | G4: Observaciones / fuente | H4: Fecha objetivo
A5: COST-001 | B5: Medir consumo real de tokens y caracteres con Application Insights y ajustar estimaciones | C5: Pendiente | D5: Media | E5: Desarrollo/Finanzas | F5: 4 | G5: El consumo actual está modelado, no medido.
A6: COST-002 | B6: Evaluar gpt-4.1-mini para consultas rutinarias y comparar calidad/coste | C6: Pendiente | D6: Media | E6: Producto/Desarrollo | F6: 4 | G6: Ahorro modelado aproximado del 80% frente a GPT-4.1.
A7: COST-003 | B7: Evaluar caché de entrada en Azure OpenAI para contexto repetido | C7: Pendiente | D7: Baja | E7: Desarrollo | F7: 3 | G7: Posible ahorro modelado aproximado del 78% en tokens de entrada en caché.
A8: COST-004 | B8: Establecer alertas de presupuesto y umbrales de consumo para voz/LLM | C8: Pendiente | D8: Alta | E8: IT/Finanzas | F8: 4 | G8: No hay control agregado de coste por usuario.
A9: COST-005 | B9: Revisar previsión de costes al crecer de 10 usuarios o aumentar concurrencia | C9: Pendiente | D9: Media | E9: IT/Finanzas | F9: 3 | G9: Estimación actual contempla 1-10 usuarios.

Sheet Estimaciones de Horas
A1: Estimaciones de Horas | J1: ↩ Índice
A2: Registro de incidencias, tareas y validaciones. Actualiza el Estado desde el desplegable; las tareas iniciales provienen de los documentos aportados y algunas requieren confirmar alcance.
A4: Incidencia / ID | B4: Descripción | C4: Estado | D4: Prioridad | E4: Responsable | F4: Estimación (h) | G4: Observaciones / fuente | H4: Fecha objetivo
A5: EST-001 | B5: Validar alcance y tarifa de la Parte A del presupuesto | C5: Por validar | D5: Media | E5: Cliente/Desarrollo | F5: 0 | G5: Presupuesto: 1.120 h × 45 €/h = 50.400 € sin IVA.
A6: EST-002 | B6: Validar alcance y tarifa de la Parte B: Conectia y producción | C6: Por validar | D6: Media | E6: Cliente/Desarrollo | F6: 0 | G6: Presupuesto: 150 h × 45 €/h = 6.750 € sin IVA, facturación aparte.
A7: EST-003 | B7: Mantener separadas horas presupuestadas y horas pendientes reales | C7: Pendiente | D7: Media | E7: Desarrollo | F7: 0 | G7: Las estimaciones del presupuesto no implican que todo el trabajo esté pendiente.
A10: PRESUPUESTO DOCUMENTADO · DESARROLLO Y PUESTA EN MARCHA
A11: Parte | B11: Concepto | C11: Horas estimadas | D11: Tarifa €/h | E11: Importe € | F11: Notas
A12: A | B12: Análisis y diseño de arquitectura | C12: 40 | D12: 45 | E12: 1800 | F12: Parte A
A13: A | B13: Núcleo y backend | C13: 120 | D13: 45 | E13: 5400 | F13: Parte A
A14: A | B14: Integración con datos corporativos | C14: 60 | D14: 45 | E14: 2700 | F14: Parte A
A15: A | B15: Motor conversacional e IA | C15: 70 | D15: 45 | E15: 3150 | F15: Parte A
A16: A | B16: Migración funcional y paridad | C16: 140 | D16: 45 | E16: 6300 | F16: Parte A
A17: A | B17: Voz (ElevenLabs) | C17: 30 | D17: 45 | E17: 1350 | F17: Parte A
A18: A | B18: Multiusuario y multilenguaje | C18: 40 | D18: 45 | E18: 1800 | F18: Parte A
A19: A | B19: Autenticación y permisos | C19: 40 | D19: 45 | E19: 1800 | F19: Parte A
A20: A | B20: Conocimiento de empresa y aprendizaje | C20: 60 | D20: 45 | E20: 2700 | F20: Parte A
A21: A | B21: Arquitectura multidominio | C21: 40 | D21: 45 | E21: 1800 | F21: Parte A
A22: A | B22: Frontend: mundos 2D, 3D y holograma | C22: 90 | D22: 45 | E22: 4050 | F22: Parte A
A23: A | B23: Mejoras funcionales | C23: 50 | D23: 45 | E23: 2250 | F23: Parte A
... A35: B | B35: Acompañamiento tras la salida | C35: 16 | D35: 45 | E35: 720 | F35: Parte B
A37: TOTAL PARTE A | C37: 1120 | D37: 45 | E37: 50400 | F37: Preproducción; sin IVA
A38: TOTAL PARTE B | C38: 150 | D38: 45 | E38: 6750 | F38: Conectia y puesta en producción; facturación aparte
A39: TOTAL GENERAL | C39: 1270 | D39: 45 | E39: 57150 | F39: Importes estimados; IVA no incluido

Sheet Costes Azure
A1: mIA · Costes operativos Azure, LLM y voz | J1: ↩ Índice
A2: Cifras de referencia extraídas de las presentaciones de costes aportadas. Los consumos de LLM/voz son escenarios modelados, no mediciones reales.
A4: Concepto | B4: Importe | C4: Unidad | D4: Observaciones
A5: Infraestructura Azure | B5: 72 | C5: €/mes | D5: Estimación fija para 1-10 usuarios; 9 servicios desplegados
A6: GPT-4.1 - perfil ligero | B6: 0.7 | C6: €/usuario/mes | D6: 5 consultas/día; modelo estimado, no consumo medido
A7: GPT-4.1 - perfil medio | B7: 2.94 | C7: €/usuario/mes | D7: 15 consultas/día; modelo estimado, no consumo medido
A8: GPT-4.1 - perfil intensivo | B8: 8.58 | C8: €/usuario/mes | D8: 30 consultas/día; modelo estimado, no consumo medido
A9: ElevenLabs - voz ocasional | B9: 1.18 | C9: €/usuario/mes | D9: 5 respuestas habladas/día; pago por uso
A10: ElevenLabs - voz intensiva | B10: 9.42 | C10: €/usuario/mes | D10: 30 respuestas habladas/día; pago por uso
A11: Escenario 1 usuario ligero (texto) | B11: 72.7 | C11: €/mes | D11: Azure 72 + LLM 0,70 + voz 0
A12: Escenario 1 usuario intensivo + voz | B12: 90 | C12: €/mes | D12: Azure 72 + LLM 8,58 + voz 9,42
A13: Escenario 5 usuarios mixtos | B13: 97.28 | C13: €/mes | D13: Azure 72 + LLM 15,86 + voz 9,42
A14: Escenario 10 usuarios mixtos | B14: 122.56 | C14: €/mes | D14: Azure 72 + LLM 31,72 + voz 18,84
A15: Azure AI Search Basic (planificado) | B15: 64.9 | C15: €/mes | D15: No desplegado hoy; no incluido en total actual
A16: Azure Machine Learning DS3 v2 (planificado) | B16: 11 | C16: €/mes mínimo modelado | D16: No desplegado hoy; depende de horas de cómputo

Sheet Mundo 2D
A1: Mundo 2D | J1: ↩ Índice
A2: Bloque de seguimiento incorporado a petición del usuario. Las tareas están propuestas y marcadas para validación; no confirman por sí mismas la implementación actual.
A4: Incidencia / ID | B4: Descripción | C4: Estado | D4: Prioridad | E4: Responsable | F4: Estimación (h) | G4: Observaciones / fuente | H4: Fecha objetivo
A5: M2D-001 | B5: Inventariar pantallas, rutas y estados de la interfaz 2D (inicio, chat, carga, error y sesión expirada). | C5: Por validar | D5: Alta | E5: Frontend | F5: 5 | G5: Nuevo bloque solicitado; confirmar qué está implementado y qué falta.
A6: M2D-002 | B6: Verificar inicio de sesión Entra ID/MSAL y envío del token al backend en todas las llamadas. | C6: Por validar | D6: Alta | E6: Frontend + IT | F6: 4 | G6: Debe reutilizar la autenticación y autorización comunes de mIA.
A7: M2D-003 | B7: Validar renderizado SSE, respuestas parciales, cancelación y recuperación ante desconexiones. | C7: Por validar | D7: Alta | E7: Frontend + Backend | F7: 6 | G7: Verificar compatibilidad con el streaming del backend real.
A8: M2D-004 | B8: Comprobar adjuntos, descarga de informes y representación de errores de permisos. | C8: Por validar | D8: Media | E8: Frontend | F8: 5 | G8: Coordinar con Tratamiento de Adjuntos e Informes y Reporting.
A9: M2D-005 | B9: Revisar diseño responsive, accesibilidad, teclado, foco y mensajes de carga. | C9: Pendiente | D9: Media | E9: Frontend + QA | F9: 5 | G9: Propuesta de validación funcional y de accesibilidad.
A10: M2D-006 | B10: Comprobar que herramientas, roles y acciones visibles coinciden con los permisos efectivos. | C10: Por validar | D10: Alta | E10: Frontend + Seguridad | F10: 4 | G10: La interfaz no debe sustituir los controles de autorización del servidor.

Sheet Mundo 3D
A1: Mundo 3D | J1: ↩ Índice
A2: Bloque de seguimiento incorporado a petición del usuario. Las tareas están propuestas y marcadas para validación; no confirman por sí mismas la implementación actual.
A4: Incidencia / ID | B4: Descripción | C4: Estado | D4: Prioridad | E4: Responsable | F4: Estimación (h) | G4: Observaciones / fuente | H4: Fecha objetivo
A5: M3D-001 | B5: Documentar tecnología de renderizado, motor, dependencias, licencias y navegadores soportados. | C5: Por validar | D5: Alta | E5: Frontend 3D + Producto | F5: 5 | G5: Decisión/estado actual no confirmado en los documentos revisados.
A6: M3D-002 | B6: Validar ciclo de vida del avatar: carga, estado de espera, escucha, respuesta, error y salida. | C6: Por validar | D6: Alta | E6: Frontend 3D | F6: 6 | G6: Asegurar coherencia con el ciclo de conversación de mIA.
A7: M3D-003 | B7: Integrar y probar voz, sincronización labial/visemas y reproducción interrumpible. | C7: Por validar | D7: Media | E7: Frontend 3D + Voz | F7: 8 | G7: Confirmar proveedor y funciones realmente activas antes de estimar el alcance final.
A8: M3D-004 | B8: Verificar streaming de texto/audio y manejo de respuestas largas, cancelación y reconexión. | C8: Por validar | D8: Alta | E8: Frontend 3D + Backend | F8: 6 | G8: Reutilizar API y sesión existentes; no duplicar reglas de negocio.
A9: M3D-005 | B9: Medir rendimiento, memoria, carga de recursos y degradación en equipos modestos. | C9: Pendiente | D9: Media | E9: Frontend 3D + QA | F9: 6 | G9: Definir objetivos medibles de fluidez y tiempo de carga.
A10: M3D-006 | B10: Validar cámara/micrófono, permisos del navegador y alternativas sin dispositivos. | C10: Por validar | D10: Alta | E10: Seguridad + Frontend | F10: 4 | G10: Aplicable si el mundo 3D utiliza entrada de audio/video.

Sheet Holograma
A1: Holograma | J1: ↩ Índice
A2: Bloque de seguimiento incorporado a petición del usuario. Las tareas están propuestas y marcadas para validación; no confirman por sí mismas la implementación actual.
A4: Incidencia / ID | B4: Descripción | C4: Estado | D4: Prioridad | E4: Responsable | F4: Estimación (h) | G4: Observaciones / fuente | H4: Fecha objetivo
A5: HLOG-001 | B5: Definir escenario holográfico: dispositivo, pantalla/proyección, sensores y distancia de interacción. | C5: Por validar | D5: Alta | E5: Producto + Hardware | F5: 6 | G5: Alcance físico y hardware pendiente de concretar.
A6: HLOG-002 | B6: Validar renderizado, orientación, escala y legibilidad en los dispositivos holográficos elegidos. | C6: Por validar | D6: Alta | E6: Frontend 3D + Hardware | F6: 8 | G6: Pruebas condicionadas a disponer del dispositivo objetivo.
A7: HLOG-003 | B7: Probar interacción por voz en entornos reales, ruido ambiental, silencios y alternativa manual. | C7: Por validar | D7: Alta | E7: Voz + QA | F7: 6 | G7: Confirmar si existe microfonía dedicada y si se activa siempre o bajo consentimiento.
A8: HLOG-004 | B8: Asegurar autenticación, permisos, cierre de sesión y caducidad en modo compartido/kiosco. | C8: Por validar | D8: Alta | E8: IT + Seguridad | F8: 5 | G8: Especial atención a sesiones abandonadas y cambio de usuario.
A9: HLOG-005 | B9: Definir privacidad visible: no mostrar datos sensibles a terceros y limpiar el estado al terminar. | C9: Por validar | D9: Alta | E9: Seguridad + Producto | F9: 5 | G9: Revisar retención local, logs, pantalla de espera y salida segura.
A10: HLOG-006 | B10: Medir disponibilidad, recuperación tras fallos y estado de conectividad del dispositivo. | C10: Pendiente | D10: Media | E10: Hardware + QA | F10: 5 | G10: Definir comprobaciones operativas y procedimiento de reinicio.

Sheet mIA-Desktop
A1: mIA-Desktop | J1: ↩ Índice
A2: Bloque de seguimiento incorporado a petición del usuario. Las tareas están propuestas y marcadas para validación; no confirman por sí mismas la implementación actual.
A4: Incidencia / ID | B4: Descripción | C4: Estado | D4: Prioridad | E4: Responsable | F4: Estimación (h) | G4: Observaciones / fuente | H4: Fecha objetivo
A5: DESK-001 | B5: Definir alcance de la app de escritorio, sistemas operativos, distribución y dependencias. | C5: Por validar | D5: Alta | E5: Producto + Desarrollo | F5: 5 | G5: La pestaña registra el bloque solicitado; no se presupone que ya exista una app.
A6: DESK-002 | B6: Diseñar autenticación Entra ID con flujo compatible con aplicación de escritorio. | C6: Por validar | D6: Alta | E6: Desarrollo + IT | F6: 6 | G6: Alinear el flujo con el tenant y las políticas corporativas.
A7: DESK-003 | B7: Proteger tokens, secretos y configuración local; evitar credenciales en texto plano. | C7: Por validar | D7: Alta | E7: Seguridad + Desarrollo | F7: 6 | G7: Revisar almacenamiento seguro específico de cada sistema operativo.
A8: DESK-004 | B8: Conectar con API/backend usando configuración de entorno segura y validación TLS. | C8: Por validar | D8: Alta | E8: Desarrollo | F8: 5 | G8: Reutilizar controles de sesión, roles y políticas del backend.
A9: DESK-005 | B9: Definir firma, empaquetado, actualización, rollback y desinstalación. | C9: Pendiente | D9: Media | E9: DevOps + IT | F9: 8 | G9: Incluir canal de distribución y gestión de versiones.
A10: DESK-006 | B10: Validar logs, telemetría, tratamiento de errores y limpieza de datos al cerrar sesión. | C10: Por validar | D10: Alta | E10: Desarrollo + Seguridad | F10: 5 | G10: Evitar registrar prompts, tokens o datos personales sin autorización.

Sheet Multiidioma
A1: Multiidioma | J1: ↩ Índice
A2: Bloque de seguimiento incorporado a petición del usuario. Las tareas están propuestas y marcadas para validación; no confirman por sí mismas la implementación actual.
A4: Incidencia / ID | B4: Descripción | C4: Estado | D4: Prioridad | E4: Responsable | F4: Estimación (h) | G4: Observaciones / fuente | H4: Fecha objetivo
A5: LANG-001 | B5: Definir idiomas iniciales, variante regional y prioridad de despliegue. | C5: Por validar | D5: Alta | E5: Producto + RR. HH. | F5: 3 | G5: Los idiomas objetivo no están especificados en las fuentes disponibles.
A6: LANG-002 | B6: Centralizar textos de interfaz en recursos de traducción y eliminar cadenas incrustadas. | C6: Por validar | D6: Alta | E6: Frontend | F6: 6 | G6: Incluir menús, botones, validaciones, errores y accesibilidad.
A7: LANG-003 | B7: Permitir selección y persistencia de idioma por usuario con detección inicial configurable. | C7: Por validar | D7: Media | E7: Frontend + Backend | F7: 5 | G7: Definir precedencia entre preferencia guardada y configuración del navegador.
A8: LANG-004 | B8: Probar instrucciones del agente, respuestas, cambio de idioma y terminología laboral. | C8: Por validar | D8: Alta | E8: IA + RR. HH. | F8: 8 | G8: Evaluar calidad y coherencia sin traducir nombres propios, cifras o normativa indebidamente.
A9: LANG-005 | B9: Revisar traducción de informes, correos, adjuntos y exportaciones generados por mIA. | C9: Por validar | D9: Alta | E9: Backend + Dominios | F9: 6 | G9: Acordar si el idioma afecta solo a la presentación o también al contenido generado.
A10: LANG-006 | B10: Validar voz por idioma: reconocimiento, pronunciación, voces disponibles y fallback a texto. | C10: Por validar | D10: Media | E10: Voz + QA | F10: 6 | G10: Depende de los proveedores/idiomas contratados realmente.
A11: LANG-007 | B11: Automatizar pruebas por idioma: formatos de fecha/número, cadenas largas y diseño. | C11: Pendiente | D11: Media | E11: QA + Frontend | F11: 6 | G11: Incluir pruebas de no-regresión y, si aplica, idiomas RTL.
